<?xml version="1.0" encoding="utf-8" ?>
<!-- This URDF was automatically created by SolidWorks to URDF Exporter! Originally created by Stephen Brawner (brawner@gmail.com) 
     Commit Version: 1.6.0-4-g7f85cfe  Build Version: 1.6.7995.38578
     For more information, please see http://wiki.ros.org/sw_urdf_exporter -->
<robot name="kuka_urdf">
    <link name="world" />
    <joint name="world_joint" type="fixed">
        <origin xyz="0 0 0" rpy="0 0 0" />
        <!-- Place the robot wherever you want -->
        <parent link="world" />
        <child link="base_link" />
        <!-- replace this name with your robot's base link -->
    </joint>
    <link name="base_link">
        <inertial>
            <origin xyz="0.00169071554591047 0.0321254082322567 0.194181706745783" rpy="0 0 0" />
            <mass value="0.01" />
            <inertia ixx="2.30199373615997" ixy="-0.0360498315195982" ixz="0.000324874783814514" iyy="1.86913360615281" iyz="0.0782647235264402" izz="2.34289554929916" />
        </inertial>
        <visual>
            <origin xyz="0 0 0" rpy="0 0 0" />
            <geometry>
                <mesh filename="package://kuka_urdf/meshes/base_link.STL" />
            </geometry>
            <material name="">
                <color rgba="0.666666666666667 0.698039215686274 0.768627450980392 1" />
            </material>
        </visual>
        <collision>
            <origin xyz="0 0 0" rpy="0 0 0" />
            <geometry>
                <mesh filename="package://kuka_urdf/meshes/base_link.STL" />
            </geometry>
        </collision>
    </link>
    <link name="link1">
        <inertial>
            <origin xyz="0.102809070026285 0.162949294249169 -0.0437095970064403" rpy="0 0 0" />
            <mass value="0.01" />
            <inertia ixx="0.361203654554275" ixy="-0.152719426643192" ixz="0.00578336930371961" iyy="0.646325092692869" iyz="0.0275014328808699" izz="0.643948586538561" />
        </inertial>
        <visual>
            <origin xyz="0 0 0" rpy="0 0 0" />
            <geometry>
                <mesh filename="package://kuka_urdf/meshes/link1.STL" />
            </geometry>
            <material name="">
                <color rgba="0.666666666666667 0.698039215686274 0.768627450980392 1" />
            </material>
        </visual>
        <collision>
            <origin xyz="0 0 0" rpy="0 0 0" />
            <geometry>
                <mesh filename="package://kuka_urdf/meshes/link1.STL" />
            </geometry>
        </collision>
    </link>
    <joint name="joint1" type="continuous">
        <origin xyz="0 -0.01 0.367" rpy="1.5708 0 -0.08443" />
        <parent link="base_link" />
        <child link="link1" />
        <axis xyz="0 1 0" />
        <limit lower="-3.14" upper="3.14" effort="100" velocity="1" />
    </joint>
    <link name="link2">
        <inertial>
            <origin xyz="0.00319543554968393 0.293900613109197 0.155091057917142" rpy="0 0 0" />
            <mass value="0.01" />
            <inertia ixx="0.59330455813527" ixy="-0.000667748977651198" ixz="0.000213051795030478" iyy="0.0591602762509172" iyz="-0.0259757342567146" izz="0.593132988208399" />
        </inertial>
        <visual>
            <origin xyz="0 0 0" rpy="0 0 0" />
            <geometry>
                <mesh filename="package://kuka_urdf/meshes/link2.STL" />
            </geometry>
            <material name="">
                <color rgba="0.666666666666667 0.698039215686274 0.768627450980392 1" />
            </material>
        </visual>
        <collision>
            <origin xyz="0 0 0" rpy="0 0 0" />
            <geometry>
                <mesh filename="package://kuka_urdf/meshes/link2.STL" />
            </geometry>
        </collision>
    </link>
    <joint name="joint2" type="continuous">
        <origin xyz="0.27514 0.27067 0" rpy="0 0 1.0978" />
        <parent link="link1" />
        <child link="link2" />
        <axis xyz="0 0 1" />
        <limit lower="-3.14" upper="3.14" effort="100" velocity="1" />
    </joint>
    <link name="link3">
        <inertial>
            <origin xyz="-0.108431854063551 -0.0174825173011943 0.0166931623604918" rpy="0 0 0" />
            <mass value="0.01" />
            <inertia ixx="0.0622431800785935" ixy="-0.00829182508100419" ixz="0.0216125023529655" iyy="0.443114343298478" iyz="0.00443933027943639" izz="0.455586882289948" />
        </inertial>
        <visual>
            <origin xyz="0 0 0" rpy="0 0 0" />
            <geometry>
                <mesh filename="package://kuka_urdf/meshes/link3.STL" />
            </geometry>
            <material name="">
                <color rgba="0.666666666666667 0.698039215686274 0.768627450980392 1" />
            </material>
        </visual>
        <collision>
            <origin xyz="0 0 0" rpy="0 0 0" />
            <geometry>
                <mesh filename="package://kuka_urdf/meshes/link3.STL" />
            </geometry>
        </collision>
    </link>
    <joint name="joint3" type="continuous">
        <origin xyz="0.003006 0.67046 0" rpy="3.1416 0 2.1712" />
        <parent link="link2" />
        <child link="link3" />
        <axis xyz="0 0 1" />
        <limit lower="-3.14" upper="3.14" effort="100" velocity="1" />
    </joint>
    <link name="link4">
        <inertial>
            <origin xyz="0.0067405596375737 0.136144607774841 0.000146066189957605" rpy="0 0 0" />
            <mass value="0.01" />
            <inertia ixx="0.0138353059805076" ixy="-0.00127244376727786" ixz="-7.82368986780341E-06" iyy="0.00431378170193686" iyz="1.88047630765234E-06" izz="0.014039768246805" />
        </inertial>
        <visual>
            <origin xyz="0 0 0" rpy="0 0 0" />
            <geometry>
                <mesh filename="package://kuka_urdf/meshes/link4.STL" />
            </geometry>
            <material name="">
                <color rgba="0.666666666666667 0.698039215686274 0.768627450980392 1" />
            </material>
        </visual>
        <collision>
            <origin xyz="0 0 0" rpy="0 0 0" />
            <geometry>
                <mesh filename="package://kuka_urdf/meshes/link4.STL" />
            </geometry>
        </collision>
    </link>
    <joint name="joint4" type="continuous">
        <origin xyz="-0.4463 -0.0225 0.033" rpy="3.1416 1.2864 -1.5708" />
        <parent link="link3" />
        <child link="link4" />
        <axis xyz="0 1 0" />
        <limit lower="-3.14" upper="3.14" effort="100" velocity="1" />
    </joint>
    <link name="link5">
        <inertial>
            <origin xyz="-0.0148054463817822 1.07375547930832E-06 0.0553734928689547" rpy="0 0 0" />
            <mass value="0.01" />
            <inertia ixx="0.00548860925507905" ixy="-6.16396633248213E-07" ixz="0.000169392757459791" iyy="0.0113184998854174" iyz="-6.2999526191212E-07" izz="0.00867768877245735" />
        </inertial>
        <visual>
            <origin xyz="0 0 0" rpy="0 0 0" />
            <geometry>
                <mesh filename="package://kuka_urdf/meshes/link5.STL" />
            </geometry>
            <material name="">
                <color rgba="0.666666666666667 0.698039215686274 0.768627450980392 1" />
            </material>
        </visual>
        <collision>
            <origin xyz="0 0 0" rpy="0 0 0" />
            <geometry>
                <mesh filename="package://kuka_urdf/meshes/link5.STL" />
            </geometry>
        </collision>
    </link>
    <joint name="joint5" type="continuous">
        <origin xyz="0 0.2202 0" rpy="1.5063 0 -3.1416" />
        <parent link="link4" />
        <child link="link5" />
        <axis xyz="1 0 0" />
        <limit lower="-3.14" upper="3.14" effort="100" velocity="1" />
    </joint>
    <link name="link6">
        <inertial>
            <origin xyz="1.88762782071805E-08 0.0845870843735267 1.13046738636768E-08" rpy="0 0 0" />
            <mass value="0.01" />
            <inertia ixx="8.74922732123857E-05" ixy="-1.56715863896756E-12" ixz="-6.35023778905382E-10" iyy="0.000129565794251722" iyz="-1.01193800340038E-12" izz="8.74928320400638E-05" />
        </inertial>
        <visual>
            <origin xyz="0 0 0" rpy="0 0 0" />
            <geometry>
                <mesh filename="package://kuka_urdf/meshes/link6.STL" />
            </geometry>
            <material name="">
                <color rgba="1 1 1 1" />
            </material>
        </visual>
        <collision>
            <origin xyz="0 0 0" rpy="0 0 0" />
            <geometry>
                <mesh filename="package://kuka_urdf/meshes/link6.STL" />
            </geometry>
        </collision>
    </link>
    <joint name="joint6" type="continuous">
        <origin xyz="-0.016 0 0.16151" rpy="1.5708 0 -0.91581" />
        <parent link="link5" />
        <child link="link6" />
        <axis xyz="0 1 0" />
        <limit lower="-3.14" upper="3.14" effort="100" velocity="1" />
    </joint>
    <link name="link7">
        <inertial>
            <origin xyz="3.33066907387547E-16 -0.0908883383174383 -6.66133814775094E-16" rpy="0 0 0" />
            <mass value="0.01" />
            <inertia ixx="5.99081865280422E-05" ixy="1.19219887326043E-19" ixz="3.3881317890172E-21" iyy="3.09203946207794E-05" iyz="-1.78935710107471E-19" izz="5.99081865280422E-05" />
        </inertial>
        <visual>
            <origin xyz="0 0 0" rpy="0 0 0" />
            <geometry>
                <mesh filename="package://kuka_urdf/meshes/link7.STL" />
            </geometry>
            <material name="">
                <color rgba="0.219607843137255 0.333333333333333 1 1" />
            </material>
        </visual>
        <collision>
            <origin xyz="0 0 0" rpy="0 0 0" />
            <geometry>
                <mesh filename="package://kuka_urdf/meshes/link7.STL" />
            </geometry>
        </collision>
    </link>
    <joint name="joint7" type="fixed">
        <origin xyz="0 0.14433 0" rpy="-3.1416 -1.2462 3.1416" />
        <parent link="link6" />
        <child link="link7" />
        <axis xyz="0 0 0" />
    </joint>
    <link name="tableBase">
        <inertial>
            <origin xyz="0 -0.0792927584491776 1.50712525224781E-17" rpy="0 0 0" />
            <mass value="22.6545515868041" />
            <inertia ixx="0.522042821248889" ixy="3.30989870144931E-17" ixz="-1.1032580492799E-17" iyy="0.435158464274667" iyz="1.07424706769485E-17" izz="0.233488306158436" />
        </inertial>
        <visual>
            <origin xyz="0 0 0" rpy="0 0 0" />
            <geometry>
                <mesh filename="package://kuka_urdf/meshes/tableBase.STL" />
            </geometry>
            <material name="">
                <color rgba="0.113725490196078 0.113725490196078 0.113725490196078 1" />
            </material>
        </visual>
        <collision>
            <origin xyz="0 0 0" rpy="0 0 0" />
            <geometry>
                <mesh filename="package://kuka_urdf/meshes/tableBase.STL" />
            </geometry>
        </collision>
    </link>
    <joint name="tableJointBase" type="fixed">
        <origin xyz="1 -0.01 0.21" rpy="1.5708 0 0" />
        <parent link="base_link" />
        <child link="tableBase" />
        <axis xyz="0 0 0" />
    </joint>
    <link name="tabelLink1">
        <inertial>
            <origin xyz="0 0.0303021162142364 1.84518277836174E-16" rpy="0 0 0" />
            <mass value="0.01" />
            <inertia ixx="0.0624189778466533" ixy="1.19244108636117E-17" ixz="1.01229731322522E-17" iyy="0.0592798871419012" iyz="-1.82557881092636E-17" izz="0.0573718491671926" />
        </inertial>
        <visual>
            <origin xyz="0 0 0" rpy="0 0 0" />
            <geometry>
                <mesh filename="package://kuka_urdf/meshes/tabelLink1.STL" />
            </geometry>
            <material name="">
                <color rgba="1 1 1 1" />
            </material>
        </visual>
        <collision>
            <origin xyz="0 0 0" rpy="0 0 0" />
            <geometry>
                <mesh filename="package://kuka_urdf/meshes/tabelLink1.STL" />
            </geometry>
        </collision>
    </link>
    <joint name="tableJoint1" type="continuous">
        <origin xyz="0 0 0" rpy="0 0 0" />
        <parent link="tableBase" />
        <child link="tabelLink1" />
        <axis xyz="0 0 1" />
    </joint>
    <link name="tableLink2">
        <inertial>
            <origin xyz="0.0482939208025785 0.0482939208025785 0.0025" rpy="0 0 0" />
            <mass value="0.01" />
            <inertia ixx="0.00232599466891" ixy="0.000752577416661154" ixz="-3.42208860332207E-19" iyy="0.00232599466891" iyz="7.22985722035411E-20" izz="0.00465064485576807" />
        </inertial>
        <visual>
            <origin xyz="0 0 0" rpy="0 0 0" />
            <geometry>
                <mesh filename="package://kuka_urdf/meshes/tableLink2.STL" />
            </geometry>
            <material name="">
                <color rgba="1 1 1 1" />
            </material>
        </visual>
        <collision>
            <origin xyz="0 0 0" rpy="0 0 0" />
            <geometry>
                <mesh filename="package://kuka_urdf/meshes/tableLink2.STL" />
            </geometry>
        </collision>
    </link>
    <joint name="tableJoint2" type="continuous">
        <origin xyz="0 0.116 0" rpy="-1.5708 0 0" />
        <parent link="tabelLink1" />
        <child link="tableLink2" />
        <axis xyz="0 0 1" />
    </joint>
    <link name="tableEeffortLink">
        <inertial>
            <origin xyz="0 0.203933823529412 -2.59511050081739E-18" rpy="0 0 0" />
            <mass value="0.01" />
            <inertia ixx="0.0189671011324169" ixy="-2.34879458835192E-35" ixz="-9.7412291491617E-35" iyy="0.0359978975332567" iyz="-9.89522079732159E-19" izz="0.0189671011324169" />
        </inertial>
        <visual>
            <origin xyz="0 0 0" rpy="0 0 0" />
            <geometry>
                <mesh filename="package://kuka_urdf/meshes/tableEeffortLink.STL" />
            </geometry>
            <material name="">
                <color rgba="1 1 1 1" />
            </material>
        </visual>
        <collision>
            <origin xyz="0 0 0" rpy="0 0 0" />
            <geometry>
                <mesh filename="package://kuka_urdf/meshes/tableEeffortLink.STL" />
            </geometry>
        </collision>
    </link>
    <joint name="tableEeffortJoint" type="fixed">
        <origin xyz="0 0 -0.175" rpy="1.5708 0 0" />
        <parent link="tableLink2" />
        <child link="tableEeffortLink" />
        <axis xyz="0 0 0" />
    </joint>
    <transmission name="trans_joint1">
        <type>transmission_interface/SimpleTransmission</type>
        <joint name="joint1">
            <hardwareInterface>hardware_interface/EffortJointInterface</hardwareInterface>
        </joint>
        <actuator name="joint1_motor">
            <hardwareInterface>hardware_interface/EffortJointInterface</hardwareInterface>
            <mechanicalReduction>1</mechanicalReduction>
        </actuator>
    </transmission>
    <transmission name="trans_joint2">
        <type>transmission_interface/SimpleTransmission</type>
        <joint name="joint2">
            <hardwareInterface>hardware_interface/EffortJointInterface</hardwareInterface>
        </joint>
        <actuator name="joint2_motor">
            <hardwareInterface>hardware_interface/EffortJointInterface</hardwareInterface>
            <mechanicalReduction>1</mechanicalReduction>
        </actuator>
    </transmission>
    <transmission name="trans_joint3">
        <type>transmission_interface/SimpleTransmission</type>
        <joint name="joint3">
            <hardwareInterface>hardware_interface/EffortJointInterface</hardwareInterface>
        </joint>
        <actuator name="joint3_motor">
            <hardwareInterface>hardware_interface/EffortJointInterface</hardwareInterface>
            <mechanicalReduction>1</mechanicalReduction>
        </actuator>
    </transmission>
    <transmission name="trans_joint4">
        <type>transmission_interface/SimpleTransmission</type>
        <joint name="joint4">
            <hardwareInterface>hardware_interface/EffortJointInterface</hardwareInterface>
        </joint>
        <actuator name="joint4_motor">
            <hardwareInterface>hardware_interface/EffortJointInterface</hardwareInterface>
            <mechanicalReduction>1</mechanicalReduction>
        </actuator>
    </transmission>
    <transmission name="trans_joint5">
        <type>transmission_interface/SimpleTransmission</type>
        <joint name="joint5">
            <hardwareInterface>hardware_interface/EffortJointInterface</hardwareInterface>
        </joint>
        <actuator name="joint5_motor">
            <hardwareInterface>hardware_interface/EffortJointInterface</hardwareInterface>
            <mechanicalReduction>1</mechanicalReduction>
        </actuator>
    </transmission>
    <transmission name="trans_joint6">
        <type>transmission_interface/SimpleTransmission</type>
        <joint name="joint6">
            <hardwareInterface>hardware_interface/EffortJointInterface</hardwareInterface>
        </joint>
        <actuator name="joint6_motor">
            <hardwareInterface>hardware_interface/EffortJointInterface</hardwareInterface>
            <mechanicalReduction>1</mechanicalReduction>
        </actuator>
    </transmission>
    <transmission name="trans_tableJoint1">
        <type>transmission_interface/SimpleTransmission</type>
        <joint name="tableJoint1">
            <hardwareInterface>hardware_interface/EffortJointInterface</hardwareInterface>
        </joint>
        <actuator name="tableJoint1_motor">
            <hardwareInterface>hardware_interface/EffortJointInterface</hardwareInterface>
            <mechanicalReduction>1</mechanicalReduction>
        </actuator>
    </transmission>
    <transmission name="trans_tableJoint2">
        <type>transmission_interface/SimpleTransmission</type>
        <joint name="tableJoint2">
            <hardwareInterface>hardware_interface/EffortJointInterface</hardwareInterface>
        </joint>
        <actuator name="tableJoint2_motor">
            <hardwareInterface>hardware_interface/EffortJointInterface</hardwareInterface>
            <mechanicalReduction>1</mechanicalReduction>
        </actuator>
    </transmission>
    <gazebo>
        <plugin name="gazebo_ros_control" filename="libgazebo_ros_control.so">
            <robotNamespace>/</robotNamespace>
        </plugin>
    </gazebo>
</robot>

