<?xml version="1.0" encoding="utf-8" ?>
<!-- This URDF was automatically created by SolidWorks to URDF Exporter! Originally created by Stephen Brawner (brawner@gmail.com) 
     Commit Version: 1.6.0-4-g7f85cfe  Build Version: 1.6.7995.38578
     For more information, please see http://wiki.ros.org/sw_urdf_exporter -->
<robot name="kuka_urdf">
    <link name="world"/>
    <joint name="world_joint" type="fixed">
        <origin xyz="0 0 0" rpy="0 0 0"/>  <!-- Place the robot wherever you want -->
        <parent link="world"/>
        <child link="base_link"/>  <!-- replace this name with your robot's base link -->
    </joint>
    <link name="base_link">
        <inertial>
            <origin xyz="0.00169071554591047 0.0421254082322567 0.194181706745783" rpy="0 0 0" />
            <mass value="72.8456791935468" />
            <inertia ixx="2.30199373615997" ixy="-0.0360498315195982" ixz="0.000324874783814514" iyy="1.86913360615281" iyz="0.0782647235264402" izz="2.34289554929916" />
        </inertial>
        <visual>
            <origin xyz="0 0 0" rpy="0 0 0" />
            <geometry>
                <mesh filename="package://kuka_urdf/meshes/base_link.STL" />
            </geometry>
            <material name="">
                <color rgba="0.666666666666667 0.698039215686274 0.768627450980392 1" />
            </material>
        </visual>
        <collision>
            <origin xyz="0 0 0" rpy="0 0 0" />
            <geometry>
                <mesh filename="package://kuka_urdf/meshes/base_link.STL" />
            </geometry>
        </collision>
    </link>
    <link name="link1">
        <inertial>
            <origin xyz="0.11850464020614 0.220299547158799 -0.0380338208389561" rpy="0 0 0" />
            <mass value="24.868772466875" />
            <inertia ixx="0.424656660940318" ixy="-0.152718990661531" ixz="0.0057839301853943" iyy="0.694343256191447" iyz="0.0275014415615462" izz="0.691966793599722" />
        </inertial>
        <visual>
            <origin xyz="0 0 0" rpy="0 0 0" />
            <geometry>
                <mesh filename="package://kuka_urdf/meshes/link1.STL" />
            </geometry>
            <material name="">
                <color rgba="0.666666666666667 0.698039215686274 0.768627450980392 1" />
            </material>
        </visual>
        <collision>
            <origin xyz="0 0 0" rpy="0 0 0" />
            <geometry>
                <mesh filename="package://kuka_urdf/meshes/link1.STL" />
            </geometry>
        </collision>
    </link>
    <joint name="joint1" type="revolute">
        <origin xyz="0 0 0.357" rpy="1.5707963267949 0 -0.0844304651404737" />
        <parent link="base_link" />
        <child link="link1" />
        <axis xyz="0 1 0" />
        <limit lower="-3.14" upper="3.14" effort="100" velocity="1" />
    </joint>
    <link name="link2">
        <inertial>
            <origin xyz="0.000189381328191018 0.303438179366152 0.155091041663287" rpy="0 0 0" />
            <mass value="13.9287878174792" />
            <inertia ixx="0.593276811357925" ixy="-0.000669711071031098" ixz="0.000213408868960804" iyy="0.0591609855193814" iyz="-0.0259775733733786" izz="0.593104027757824" />
        </inertial>
        <visual>
            <origin xyz="0 0 0" rpy="0 0 0" />
            <geometry>
                <mesh filename="package://kuka_urdf/meshes/link2.STL" />
            </geometry>
            <material name="">
                <color rgba="0.666666666666667 0.698039215686274 0.768627450980392 1" />
            </material>
        </visual>
        <collision>
            <origin xyz="0 0 0" rpy="0 0 0" />
            <geometry>
                <mesh filename="package://kuka_urdf/meshes/link2.STL" />
            </geometry>
        </collision>
    </link>
    <joint name="joint2" type="revolute">
        <origin xyz="0.285000000000002 0.278999999999999 0" rpy="0 0 0.860540949726414" />
        <parent link="link1" />
        <child link="link2" />
        <axis xyz="0 0 1" />
        <limit lower="-3.14" upper="3.14" effort="100" velocity="1" />
    </joint>
    <link name="link3">
        <inertial>
            <origin xyz="-0.04700413682585 -0.0176944777360042 0.0276625988132613" rpy="0 0 0" />
            <mass value="16.4189284998869" />
            <inertia ixx="0.0681231627534655" ixy="-0.00829241688235473" ixz="0.0216145830359155" iyy="0.456794458430376" iyz="0.00443789755446783" izz="0.466037810686351" />
        </inertial>
        <visual>
            <origin xyz="0 0 0" rpy="0 0 0" />
            <geometry>
                <mesh filename="package://kuka_urdf/meshes/link3.STL" />
            </geometry>
            <material name="">
                <color rgba="0.666666666666667 0.698039215686274 0.768627450980392 1" />
            </material>
        </visual>
        <collision>
            <origin xyz="0 0 0" rpy="0 0 0" />
            <geometry>
                <mesh filename="package://kuka_urdf/meshes/link3.STL" />
            </geometry>
        </collision>
    </link>
    <joint name="joint3" type="revolute">
        <origin xyz="0 0.680000000000002 0" rpy="-3.14159265358979 0 2.25375212776307" />
        <parent link="link2" />
        <child link="link3" />
        <axis xyz="0 0 1" />
        <limit lower="-3.14" upper="3.14" effort="100" velocity="1" />
    </joint>
    <link name="link4">
        <inertial>
            <origin xyz="0.0067405769845435 0.119400386730787 0.000146014653053195" rpy="0 0 0" />
            <mass value="2.38078194379471" />
            <inertia ixx="0.0138352592752633" ixy="-0.0012724264079337" ixz="-7.82821068847847E-06" iyy="0.00431375628504729" iyz="1.88244486105921E-06" izz="0.0140397202358096" />
        </inertial>
        <visual>
            <origin xyz="0 0 0" rpy="0 0 0" />
            <geometry>
                <mesh filename="package://kuka_urdf/meshes/link4.STL" />
            </geometry>
            <material name="">
                <color rgba="0.666666666666667 0.698039215686274 0.768627450980392 1" />
            </material>
        </visual>
        <collision>
            <origin xyz="0 0 0" rpy="0 0 0" />
            <geometry>
                <mesh filename="package://kuka_urdf/meshes/link4.STL" />
            </geometry>
        </collision>
    </link>
    <joint name="joint4" type="revolute">
        <origin xyz="-0.463043248331428 -0.0225000000000002 0.0330000000000008" rpy="3.14159265358979 -1.03989491708518 -1.57079632679491" />
        <parent link="link3" />
        <child link="link4" />
        <axis xyz="0 1 0" />
        <limit lower="-3.14" upper="3.14" effort="100" velocity="1" />
    </joint>
    <link name="link5">
        <inertial>
            <origin xyz="-0.0158164557924105 9.19753188277639E-07 0.0563361689596945" rpy="0 0 0" />
            <mass value="1.80204110195789" />
            <inertia ixx="0.00560825722244345" ixy="-6.28023344812325E-07" ixz="0.000237113370095094" iyy="0.0114817936089823" iyz="-6.22321567802891E-07" izz="0.00875151562088488" />
        </inertial>
        <visual>
            <origin xyz="0 0 0" rpy="0 0 0" />
            <geometry>
                <mesh filename="package://kuka_urdf/meshes/link5.STL" />
            </geometry>
            <material name="">
                <color rgba="0.666666666666667 0.698039215686274 0.768627450980392 1" />
            </material>
        </visual>
        <collision>
            <origin xyz="0 0 0" rpy="0 0 0" />
            <geometry>
                <mesh filename="package://kuka_urdf/meshes/link5.STL" />
            </geometry>
        </collision>
    </link>
    <joint name="joint5" type="revolute">
        <origin xyz="0 0.203456751668462 0" rpy="1.69866961467948 0 -3.14159265358972" />
        <parent link="link4" />
        <child link="link5" />
        <axis xyz="1 0 0" />
        <limit lower="-3.14" upper="3.14" effort="100" velocity="1" />
    </joint>
    <link name="link6">
        <inertial>
            <origin xyz="1.56889810032368E-08 0.0607892928273234 1.35196158712603E-08" rpy="0 0 0" />
            <mass value="0.21569144856326" />
            <inertia ixx="8.74922726987973E-05" ixy="-2.61522195322773E-13" ixz="-6.33886408899267E-10" iyy="0.000129565791188478" iyz="-1.35094136343338E-13" izz="8.74928287712893E-05" />
        </inertial>
        <visual>
            <origin xyz="0 0 0" rpy="0 0 0" />
            <geometry>
                <mesh filename="package://kuka_urdf/meshes/link6.STL" />
            </geometry>
            <material name="">
                <color rgba="1 1 1 1" />
            </material>
        </visual>
        <collision>
            <origin xyz="0 0 0" rpy="0 0 0" />
            <geometry>
                <mesh filename="package://kuka_urdf/meshes/link6.STL" />
            </geometry>
        </collision>
    </link>
    <joint name="joint6" type="revolute">
        <origin xyz="-0.0160000000004577 0 0.185308798192681" rpy="1.57079632679489 0 2.12309994244728" />
        <parent link="link5" />
        <child link="link6" />
        <axis xyz="0 1 0" />
        <limit lower="-3.14" upper="3.14" effort="100" velocity="1" />
    </joint>
    <transmission name="trans_joint1">
        <type>transmission_interface/SimpleTransmission</type>
        <joint name="joint1">
            <hardwareInterface>hardware_interface/PositionJointInterface</hardwareInterface>
        </joint>
        <actuator name="joint1_motor">
            <hardwareInterface>hardware_interface/PositionJointInterface</hardwareInterface>
            <mechanicalReduction>1</mechanicalReduction>
        </actuator>
    </transmission>
    <transmission name="trans_joint2">
        <type>transmission_interface/SimpleTransmission</type>
        <joint name="joint2">
            <hardwareInterface>hardware_interface/PositionJointInterface</hardwareInterface>
        </joint>
        <actuator name="joint2_motor">
            <hardwareInterface>hardware_interface/PositionJointInterface</hardwareInterface>
            <mechanicalReduction>1</mechanicalReduction>
        </actuator>
    </transmission>
    <transmission name="trans_joint3">
        <type>transmission_interface/SimpleTransmission</type>
        <joint name="joint3">
            <hardwareInterface>hardware_interface/PositionJointInterface</hardwareInterface>
        </joint>
        <actuator name="joint3_motor">
            <hardwareInterface>hardware_interface/PositionJointInterface</hardwareInterface>
            <mechanicalReduction>1</mechanicalReduction>
        </actuator>
    </transmission>
    <transmission name="trans_joint4">
        <type>transmission_interface/SimpleTransmission</type>
        <joint name="joint4">
            <hardwareInterface>hardware_interface/PositionJointInterface</hardwareInterface>
        </joint>
        <actuator name="joint4_motor">
            <hardwareInterface>hardware_interface/PositionJointInterface</hardwareInterface>
            <mechanicalReduction>1</mechanicalReduction>
        </actuator>
    </transmission>
    <transmission name="trans_joint5">
        <type>transmission_interface/SimpleTransmission</type>
        <joint name="joint5">
            <hardwareInterface>hardware_interface/PositionJointInterface</hardwareInterface>
        </joint>
        <actuator name="joint5_motor">
            <hardwareInterface>hardware_interface/PositionJointInterface</hardwareInterface>
            <mechanicalReduction>1</mechanicalReduction>
        </actuator>
    </transmission>
    <transmission name="trans_joint6">
        <type>transmission_interface/SimpleTransmission</type>
        <joint name="joint6">
            <hardwareInterface>hardware_interface/PositionJointInterface</hardwareInterface>
        </joint>
        <actuator name="joint6_motor">
            <hardwareInterface>hardware_interface/PositionJointInterface</hardwareInterface>
            <mechanicalReduction>1</mechanicalReduction>
        </actuator>
    </transmission>
    <gazebo>
        <plugin name="gazebo_ros_control" filename="libgazebo_ros_control.so">
            <robotNamespace>/</robotNamespace>
        </plugin>
    </gazebo>
</robot>

