<?xml version="1.0" encoding="utf-8" ?>
<!-- This URDF was automatically created by SolidWorks to URDF Exporter! Originally created by Stephen Brawner (brawner@gmail.com) 
     Commit Version: 1.6.0-4-g7f85cfe  Build Version: 1.6.7995.38578
     For more information, please see http://wiki.ros.org/sw_urdf_exporter -->
<robot name="kuka_urdf">
    <link name="world"/>
    <joint name="world_joint" type="fixed">
        <origin xyz="0 0 0" rpy="0 0 0"/>  <!-- Place the robot wherever you want -->
        <parent link="world"/>
        <child link="base_link"/>  <!-- replace this name with your robot's base link -->
    </joint>
    <link name="base_link">
        <inertial>
            <origin xyz="0.00169071554591047 0.0421254082322567 0.194181706745783" rpy="0 0 0" />
            <mass value="72.8456791935468" />
            <inertia ixx="2.30199373615997" ixy="-0.0360498315195982" ixz="0.000324874783814513" iyy="1.86913360615281" iyz="0.0782647235264402" izz="2.34289554929916" />
        </inertial>
        <visual>
            <origin xyz="0 0 0" rpy="0 0 0" />
            <geometry>
                <mesh filename="package://kuka_urdf/meshes/base_link.STL" />
            </geometry>
            <material name="">
                <color rgba="0.666666666666667 0.698039215686274 0.768627450980392 1" />
            </material>
        </visual>
        <collision>
            <origin xyz="0 0 0" rpy="0 0 0" />
            <geometry>
                <mesh filename="package://kuka_urdf/meshes/base_link.STL" />
            </geometry>
        </collision>
    </link>
    <link name="link1">
        <inertial>
            <origin xyz="0.1185 0.2203 -0.038034" rpy="0 0 0" />
            <mass value="24.869" />
            <inertia ixx="0.42466" ixy="-0.15272" ixz="0.0057839" iyy="0.69434" iyz="0.027501" izz="0.69197" />
        </inertial>
        <visual>
            <origin xyz="0 0 0" rpy="0 0 0" />
            <geometry>
                <mesh filename="package://kuka_urdf/meshes/link1.STL" />
            </geometry>
            <material name="">
                <color rgba="0.66667 0.69804 0.76863 1" />
            </material>
        </visual>
        <collision>
            <origin xyz="0 0 0" rpy="0 0 0" />
            <geometry>
                <mesh filename="package://kuka_urdf/meshes/link1.STL" />
            </geometry>
        </collision>
    </link>
    <joint name="joint1" type="continuous">
        <origin xyz="0 0 0.357" rpy="1.5707963267949 0 -0.0844304651404737" />
        <parent link="base_link" />
        <child link="link1" />
        <axis xyz="0 1 0" />
        <limit lower="-3.14" upper="3.14" effort="100" velocity="1" />
    </joint>
    <link name="link2">
        <inertial>
            <origin xyz="0.00018938 0.30344 0.15509" rpy="0 0 0" />
            <mass value="13.929" />
            <inertia ixx="0.59328" ixy="-0.00066971" ixz="0.00021341" iyy="0.059161" iyz="-0.025978" izz="0.5931" />
        </inertial>
        <visual>
            <origin xyz="0 0 0" rpy="0 0 0" />
            <geometry>
                <mesh filename="package://kuka_urdf/meshes/link2.STL" />
            </geometry>
            <material name="">
                <color rgba="0.66667 0.69804 0.76863 1" />
            </material>
        </visual>
        <collision>
            <origin xyz="0 0 0" rpy="0 0 0" />
            <geometry>
                <mesh filename="package://kuka_urdf/meshes/link2.STL" />
            </geometry>
        </collision>
    </link>
    <joint name="joint2" type="revolute">
        <origin xyz="0.285 0.279 0" rpy="0 0 0.86054" />
        <parent link="link1" />
        <child link="link2" />
        <axis xyz="0 0 1" />
        <limit lower="-3.14" upper="3.14" effort="100" velocity="1" />
    </joint>
    <link name="link3">
        <inertial>
            <origin xyz="-0.047004 -0.017694 0.027663" rpy="0 0 0" />
            <mass value="16.419" />
            <inertia ixx="0.068123" ixy="-0.0082924" ixz="0.021615" iyy="0.45679" iyz="0.0044379" izz="0.46604" />
        </inertial>
        <visual>
            <origin xyz="0 0 0" rpy="0 0 0" />
            <geometry>
                <mesh filename="package://kuka_urdf/meshes/link3.STL" />
            </geometry>
            <material name="">
                <color rgba="0.66667 0.69804 0.76863 1" />
            </material>
        </visual>
        <collision>
            <origin xyz="0 0 0" rpy="0 0 0" />
            <geometry>
                <mesh filename="package://kuka_urdf/meshes/link3.STL" />
            </geometry>
        </collision>
    </link>
    <joint name="joint3" type="revolute">
        <origin xyz="0 0.68 0" rpy="-3.1416 0 2.2538" />
        <parent link="link2" />
        <child link="link3" />
        <axis xyz="0 0 1" />
        <limit lower="-3.14" upper="3.14" effort="100" velocity="1" />
    </joint>
    <link name="link4">
        <inertial>
            <origin xyz="0.00674057698454339 0.119400386730787 0.000146014653052973" rpy="0 0 0" />
            <mass value="2.38078194379471" />
            <inertia ixx="0.0138352592752633" ixy="-0.0012724264079337" ixz="-7.82821068847934E-06" iyy="0.00431375628504729" iyz="1.88244486105927E-06" izz="0.0140397202358096" />
        </inertial>
        <visual>
            <origin xyz="0 0 0" rpy="0 0 0" />
            <geometry>
                <mesh filename="package://kuka_urdf/meshes/link4.STL" />
            </geometry>
            <material name="">
                <color rgba="0.666666666666667 0.698039215686274 0.768627450980392 1" />
            </material>
        </visual>
        <collision>
            <origin xyz="0 0 0" rpy="0 0 0" />
            <geometry>
                <mesh filename="package://kuka_urdf/meshes/link4.STL" />
            </geometry>
        </collision>
    </link>
    <joint name="joint4" type="continuous">
        <origin xyz="-0.46304 -0.0225 0.033" rpy="3.1416 -1.0399 -1.5708" />
        <parent link="link3" />
        <child link="link4" />
        <axis xyz="0 1 0" />
        <limit lower="-3.14" upper="3.14" effort="100" velocity="1" />
    </joint>
    <link name="link5">
        <inertial>
            <origin xyz="-0.0148056264551854 9.54624306492846E-07 0.0553736298877739" rpy="0 0 0" />
            <mass value="1.73399119088313" />
            <inertia ixx="0.00548862491579296" ixy="-6.2456122592214E-07" ixz="0.000169357529165341" iyy="0.0113184795859753" iyz="-6.27246910990676E-07" izz="0.00867767361478413" />
        </inertial>
        <visual>
            <origin xyz="0 0 0" rpy="0 0 0" />
            <geometry>
                <mesh filename="package://kuka_urdf/meshes/link5.STL" />
            </geometry>
            <material name="">
                <color rgba="0.666666666666667 0.698039215686274 0.768627450980392 1" />
            </material>
        </visual>
        <collision>
            <origin xyz="0 0 0" rpy="0 0 0" />
            <geometry>
                <mesh filename="package://kuka_urdf/meshes/link5.STL" />
            </geometry>
        </collision>
    </link>
    <joint name="joint5" type="revolute">
        <origin xyz="0 0.20346 0" rpy="1.6987 0 -3.1416" />
        <parent link="link4" />
        <child link="link5" />
        <axis xyz="1 0 0" />
        <limit lower="-3.14" upper="3.14" effort="100" velocity="1" />
    </joint>
    <link name="link6">
        <inertial>
            <origin xyz="1.56889810032368E-08 0.0607892928273234 1.35196158851381E-08" rpy="0 0 0" />
            <mass value="0.21569144856326" />
            <inertia ixx="8.74922726987973E-05" ixy="-2.61522198373415E-13" ixz="-6.33886408897679E-10" iyy="0.000129565791188478" iyz="-1.35094123849602E-13" izz="8.74928287712893E-05" />
        </inertial>
        <visual>
            <origin xyz="0 0 0" rpy="0 0 0" />
            <geometry>
                <mesh filename="package://kuka_urdf/meshes/link6.STL" />
            </geometry>
            <material name="">
                <color rgba="1 1 1 1" />
            </material>
        </visual>
        <collision>
            <origin xyz="0 0 0" rpy="0 0 0" />
            <geometry>
                <mesh filename="package://kuka_urdf/meshes/link6.STL" />
            </geometry>
        </collision>
    </link>
    <joint name="joint6" type="continuous">
        <origin xyz="-0.016 0 0.18531" rpy="1.5708 0 2.1231" />
        <parent link="link5" />
        <child link="link6" />
        <axis xyz="0 1 0" />
        <limit lower="-3.14" upper="3.14" effort="100" velocity="1" />
    </joint>
    <link name="link7">
        <inertial>
            <origin xyz="-0.090558425024217 -0.00753074319557223 -0.00177471297982487" rpy="0 0 0" />
            <mass value="0.0603242087036552" />
            <inertia ixx="3.113045679136E-05" ixy="-2.39312567925715E-06" ixz="-5.63969729817243E-07" iyy="5.97091767184042E-05" iyz="-4.68991284266896E-08" izz="5.98971341671003E-05" />
        </inertial>
        <visual>
            <origin xyz="0 0 0" rpy="0 0 0" />
            <geometry>
                <mesh filename="package://kuka_urdf/meshes/link7.STL" />
            </geometry>
            <material name="">
                <color rgba="0.219607843137255 0.333333333333333 1 1" />
            </material>
        </visual>
        <collision>
            <origin xyz="0 0 0" rpy="0 0 0" />
            <geometry>
                <mesh filename="package://kuka_urdf/meshes/link7.STL" />
            </geometry>
        </collision>
    </link>
    <joint name="joint7" type="fixed">
        <origin xyz="0 0.10377 0" rpy="-0.019531 0.017968 1.4875" />
        <parent link="link6" />
        <child link="link7" />
        <axis xyz="0 0 0" />
    </joint>
    <transmission name="trans_joint1">
        <type>transmission_interface/SimpleTransmission</type>
        <joint name="joint1">
            <hardwareInterface>hardware_interface/EffortJointInterface</hardwareInterface>
        </joint>
        <actuator name="joint1_motor">
            <hardwareInterface>hardware_interface/EffortJointInterface</hardwareInterface>
            <mechanicalReduction>1</mechanicalReduction>
        </actuator>
    </transmission>
    <transmission name="trans_joint2">
        <type>transmission_interface/SimpleTransmission</type>
        <joint name="joint2">
            <hardwareInterface>hardware_interface/EffortJointInterface</hardwareInterface>
        </joint>
        <actuator name="joint2_motor">
            <hardwareInterface>hardware_interface/EffortJointInterface</hardwareInterface>
            <mechanicalReduction>1</mechanicalReduction>
        </actuator>
    </transmission>
    <transmission name="trans_joint3">
        <type>transmission_interface/SimpleTransmission</type>
        <joint name="joint3">
            <hardwareInterface>hardware_interface/EffortJointInterface</hardwareInterface>
        </joint>
        <actuator name="joint3_motor">
            <hardwareInterface>hardware_interface/EffortJointInterface</hardwareInterface>
            <mechanicalReduction>1</mechanicalReduction>
        </actuator>
    </transmission>
    <transmission name="trans_joint4">
        <type>transmission_interface/SimpleTransmission</type>
        <joint name="joint4">
            <hardwareInterface>hardware_interface/EffortJointInterface</hardwareInterface>
        </joint>
        <actuator name="joint4_motor">
            <hardwareInterface>hardware_interface/EffortJointInterface</hardwareInterface>
            <mechanicalReduction>1</mechanicalReduction>
        </actuator>
    </transmission>
    <transmission name="trans_joint5">
        <type>transmission_interface/SimpleTransmission</type>
        <joint name="joint5">
            <hardwareInterface>hardware_interface/EffortJointInterface</hardwareInterface>
        </joint>
        <actuator name="joint5_motor">
            <hardwareInterface>hardware_interface/EffortJointInterface</hardwareInterface>
            <mechanicalReduction>1</mechanicalReduction>
        </actuator>
    </transmission>
    <transmission name="trans_joint6">
        <type>transmission_interface/SimpleTransmission</type>
        <joint name="joint6">
            <hardwareInterface>hardware_interface/EffortJointInterface</hardwareInterface>
        </joint>
        <actuator name="joint6_motor">
            <hardwareInterface>hardware_interface/EffortJointInterface</hardwareInterface>
            <mechanicalReduction>1</mechanicalReduction>
        </actuator>
    </transmission>
    <gazebo>
        <plugin name="gazebo_ros_control" filename="libgazebo_ros_control.so">
            <robotNamespace>/</robotNamespace>
        </plugin>
    </gazebo>
</robot>

