<?xml version="1.0" encoding="utf-8" ?>
<!-- This URDF was automatically created by SolidWorks to URDF Exporter! Originally created by Stephen Brawner (brawner@gmail.com) 
     Commit Version: 1.6.0-4-g7f85cfe  Build Version: 1.6.7995.38578
     For more information, please see http://wiki.ros.org/sw_urdf_exporter -->
<robot name="kuka_urdf">
    <link name="world" />
    <joint name="world_joint" type="fixed">
        <origin xyz="0 0 0" rpy="0 0 0" />
        <!-- Place the robot wherever you want -->
        <parent link="world" />
        <child link="base_link" />
        <!-- replace this name with your robot's base link -->
    </joint>
    <link name="base_link">
        <inertial>
            <origin xyz="0.0016907 0.032125 0.19418" rpy="0 0 0" />
            <mass value="72.846" />
            <inertia ixx="2.302" ixy="-0.03605" ixz="0.00032487" iyy="1.8691" iyz="0.078265" izz="2.3429" />
        </inertial>
        <visual>
            <origin xyz="0 0 0" rpy="0 0 0" />
            <geometry>
                <mesh filename="package://kuka_urdf/meshes/base_link.STL" />
            </geometry>
            <material name="">
                <color rgba="0.66667 0.69804 0.76863 1" />
            </material>
        </visual>
        <collision>
            <origin xyz="0 0 0" rpy="0 0 0" />
            <geometry>
                <mesh filename="package://kuka_urdf/meshes/base_link.STL" />
            </geometry>
        </collision>
    </link>
    <link name="link1">
        <inertial>
            <origin xyz="0.10281 0.16295 -0.04371" rpy="0 0 0" />
            <mass value="0.060324" />
            <inertia ixx="0.3612" ixy="-0.15272" ixz="0.0057834" iyy="0.64633" iyz="0.027501" izz="0.64395" />
        </inertial>
        <visual>
            <origin xyz="0 0 0" rpy="0 0 0" />
            <geometry>
                <mesh filename="package://kuka_urdf/meshes/link1.STL" />
            </geometry>
            <material name="">
                <color rgba="0.66667 0.69804 0.76863 1" />
            </material>
        </visual>
        <collision>
            <origin xyz="0 0 0" rpy="0 0 0" />
            <geometry>
                <mesh filename="package://kuka_urdf/meshes/link1.STL" />
            </geometry>
        </collision>
    </link>
    <joint name="joint1" type="continuous">
        <origin xyz="0 -0.00999999999999998 0.367" rpy="1.5707963267949 0 -0.0844304651404737" />
        <parent link="base_link" />
        <child link="link1" />
        <axis xyz="0 1 0" />
        <limit lower="-3.14" upper="3.14" effort="100" velocity="1" />
    </joint>
    <link name="link2">
        <inertial>
            <origin xyz="0.0031954 0.2939 0.15509" rpy="0 0 0" />
            <mass value="0.060324" />
            <inertia ixx="0.5933" ixy="-0.00066775" ixz="0.00021305" iyy="0.05916" iyz="-0.025976" izz="0.59313" />
        </inertial>
        <visual>
            <origin xyz="0 0 0" rpy="0 0 0" />
            <geometry>
                <mesh filename="package://kuka_urdf/meshes/link2.STL" />
            </geometry>
            <material name="">
                <color rgba="0.66667 0.69804 0.76863 1" />
            </material>
        </visual>
        <collision>
            <origin xyz="0 0 0" rpy="0 0 0" />
            <geometry>
                <mesh filename="package://kuka_urdf/meshes/link2.STL" />
            </geometry>
        </collision>
    </link>
    <joint name="joint2" type="continuous">
        <origin xyz="0.2751402982579 0.270669215850882 0" rpy="0 0 1.09776733459367" />
        <parent link="link1" />
        <child link="link2" />
        <axis xyz="0 0 1" />
        <limit lower="-3.14" upper="3.14" effort="100" velocity="1" />
    </joint>
    <link name="link3">
        <inertial>
            <origin xyz="-0.10843 -0.017483 0.016693" rpy="0 0 0" />
            <mass value="0.060324" />
            <inertia ixx="0.062243" ixy="-0.0082918" ixz="0.021613" iyy="0.44311" iyz="0.0044393" izz="0.45559" />
        </inertial>
        <visual>
            <origin xyz="0 0 0" rpy="0 0 0" />
            <geometry>
                <mesh filename="package://kuka_urdf/meshes/link3.STL" />
            </geometry>
            <material name="">
                <color rgba="0.66667 0.69804 0.76863 1" />
            </material>
        </visual>
        <collision>
            <origin xyz="0 0 0" rpy="0 0 0" />
            <geometry>
                <mesh filename="package://kuka_urdf/meshes/link3.STL" />
            </geometry>
        </collision>
    </link>
    <joint name="joint3" type="continuous">
        <origin xyz="0.00300600653973404 0.670462499033651 0" rpy="3.14159265358979 0 2.17118981711903" />
        <parent link="link2" />
        <child link="link3" />
        <axis xyz="0 0 1" />
        <limit lower="-3.14" upper="3.14" effort="100" velocity="1" />
    </joint>
    <link name="link4">
        <inertial>
            <origin xyz="0.0067406 0.13614 0.00014607" rpy="0 0 0" />
            <mass value="0.060324" />
            <inertia ixx="0.013835" ixy="-0.0012724" ixz="-7.8237E-06" iyy="0.0043138" iyz="1.8805E-06" izz="0.01404" />
        </inertial>
        <visual>
            <origin xyz="0 0 0" rpy="0 0 0" />
            <geometry>
                <mesh filename="package://kuka_urdf/meshes/link4.STL" />
            </geometry>
            <material name="">
                <color rgba="0.66667 0.69804 0.76863 1" />
            </material>
        </visual>
        <collision>
            <origin xyz="0 0 0" rpy="0 0 0" />
            <geometry>
                <mesh filename="package://kuka_urdf/meshes/link4.STL" />
            </geometry>
        </collision>
    </link>
    <joint name="joint4" type="continuous">
        <origin xyz="-0.44629918087112 -0.0224999999999995 0.032999999999999" rpy="3.14159265358979 1.28637430236672 -1.5707963267949" />
        <parent link="link3" />
        <child link="link4" />
        <axis xyz="0 1 0" />
        <limit lower="-3.14" upper="3.14" effort="100" velocity="1" />
    </joint>
    <link name="link5">
        <inertial>
            <origin xyz="-0.014805 1.0738E-06 0.055373" rpy="0 0 0" />
            <mass value="0.060324" />
            <inertia ixx="0.0054886" ixy="-6.1639E-07" ixz="0.00016939" iyy="0.011318" iyz="-6.3E-07" izz="0.0086777" />
        </inertial>
        <visual>
            <origin xyz="0 0 0" rpy="0 0 0" />
            <geometry>
                <mesh filename="package://kuka_urdf/meshes/link5.STL" />
            </geometry>
            <material name="">
                <color rgba="0.66667 0.69804 0.76863 1" />
            </material>
        </visual>
        <collision>
            <origin xyz="0 0 0" rpy="0 0 0" />
            <geometry>
                <mesh filename="package://kuka_urdf/meshes/link5.STL" />
            </geometry>
        </collision>
    </link>
    <joint name="joint5" type="continuous">
        <origin xyz="0 0.220200819128881 0" rpy="1.50631561095374 0 -3.14159265358979" />
        <parent link="link4" />
        <child link="link5" />
        <axis xyz="1 0 0" />
        <limit lower="-3.14" upper="3.14" effort="100" velocity="1" />
    </joint>
    <link name="link6">
        <inertial>
            <origin xyz="1.8876E-08 0.084587 1.1305E-08" rpy="0 0 0" />
            <mass value="0.060324" />
            <inertia ixx="8.7492E-05" ixy="-1.5672E-12" ixz="-6.3502E-10" iyy="0.00012957" iyz="-1.0119E-12" izz="8.7493E-05" />
        </inertial>
        <visual>
            <origin xyz="0 0 0" rpy="0 0 0" />
            <geometry>
                <mesh filename="package://kuka_urdf/meshes/link6.STL" />
            </geometry>
            <material name="">
                <color rgba="1 1 1 1" />
            </material>
        </visual>
        <collision>
            <origin xyz="0 0 0" rpy="0 0 0" />
            <geometry>
                <mesh filename="package://kuka_urdf/meshes/link6.STL" />
            </geometry>
        </collision>
    </link>
    <joint name="joint6" type="continuous">
        <origin xyz="-0.0159999999999904 0 0.161511009128483" rpy="1.5707963267949 0 -0.91580856418439" />
        <parent link="link5" />
        <child link="link6" />
        <axis xyz="0 1 0" />
        <limit lower="-3.14" upper="3.14" effort="100" velocity="1" />
    </joint>
    <link name="link7">
        <inertial>
            <origin xyz="-4.4409E-16 0.019112 1.1102E-16" rpy="0 0 0" />
            <mass value="0.060324" />
            <inertia ixx="5.9908E-05" ixy="1.1964E-19" ixz="-5.0822E-21" iyy="3.092E-05" iyz="-1.8624E-19" izz="5.9908E-05" />
        </inertial>
        <visual>
            <origin xyz="0 0 0" rpy="0 0 0" />
            <geometry>
                <mesh filename="package://kuka_urdf/meshes/link7.STL" />
            </geometry>
            <material name="">
                <color rgba="0.21961 0.33333 1 1" />
            </material>
        </visual>
        <collision>
            <origin xyz="0 0 0" rpy="0 0 0" />
            <geometry>
                <mesh filename="package://kuka_urdf/meshes/link7.STL" />
            </geometry>
        </collision>
    </link>
    <joint name="joint7" type="fixed">
        <origin xyz="0 0.0343289908715182 0" rpy="-3.14159265358978 -1.24624974571635 3.14159265358977" />
        <parent link="link6" />
        <child link="link7" />
        <axis xyz="0 0 0" />
    </joint>
    <link name="tableBase">
        <inertial>
            <origin xyz="0 -0.079293 1.1486E-17" rpy="0 0 0" />
            <mass value="22.655" />
            <inertia ixx="0.52204" ixy="3.0392E-17" ixz="-1.1033E-17" iyy="0.43516" iyz="1.0371E-17" izz="0.23349" />
        </inertial>
        <visual>
            <origin xyz="0 0 0" rpy="0 0 0" />
            <geometry>
                <mesh filename="package://kuka_urdf/meshes/tableBase.STL" />
            </geometry>
            <material name="">
                <color rgba="0.11373 0.11373 0.11373 1" />
            </material>
        </visual>
        <collision>
            <origin xyz="0 0 0" rpy="0 0 0" />
            <geometry>
                <mesh filename="package://kuka_urdf/meshes/tableBase.STL" />
            </geometry>
        </collision>
    </link>
    <joint name="tableJointBase" type="fixed">
        <origin xyz="1 -0.01 0.21" rpy="1.5708 0 0" />
        <parent link="base_link" />
        <child link="tableBase" />
        <axis xyz="0 0 0" />
    </joint>
    <link name="tabelLink1">
        <inertial>
            <origin xyz="0 0.030302 1.8336E-16" rpy="0 0 0" />
            <mass value="0.060324" />
            <inertia ixx="0.062419" ixy="1.2666E-17" ixz="1.0072E-17" iyy="0.05928" iyz="-2.8778E-17" izz="0.057372" />
        </inertial>
        <visual>
            <origin xyz="0 0 0" rpy="0 0 0" />
            <geometry>
                <mesh filename="package://kuka_urdf/meshes/tabelLink1.STL" />
            </geometry>
            <material name="">
                <color rgba="1 1 1 1" />
            </material>
        </visual>
        <collision>
            <origin xyz="0 0 0" rpy="0 0 0" />
            <geometry>
                <mesh filename="package://kuka_urdf/meshes/tabelLink1.STL" />
            </geometry>
        </collision>
    </link>
    <joint name="tableJoint1" type="continuous">
        <origin xyz="0 0 0" rpy="0 0 0" />
        <parent link="tableBase" />
        <child link="tabelLink1" />
        <axis xyz="0 0 1" />
    </joint>
    <link name="tableLink2">
        <inertial>
            <origin xyz="0.048294 0.048294 0.0025" rpy="0 0 0" />
            <mass value="0.32268" />
            <inertia ixx="0.002326" ixy="0.00075258" ixz="-3.4381E-19" iyy="0.002326" iyz="7.5753E-20" izz="0.0046506" />
        </inertial>
        <visual>
            <origin xyz="0 0 0" rpy="0 0 0" />
            <geometry>
                <mesh filename="package://kuka_urdf/meshes/tableLink2.STL" />
            </geometry>
            <material name="">
                <color rgba="1 1 1 1" />
            </material>
        </visual>
        <collision>
            <origin xyz="0 0 0" rpy="0 0 0" />
            <geometry>
                <mesh filename="package://kuka_urdf/meshes/tableLink2.STL" />
            </geometry>
        </collision>
    </link>
    <joint name="tableJoint2" type="continuous">
        <origin xyz="0 0.116 0" rpy="-1.5708 0 0" />
        <parent link="tabelLink1" />
        <child link="tableLink2" />
        <axis xyz="0 0 1" />
    </joint>
    <link name="tableEeffortLink">
        <inertial>
            <origin xyz="0 0.039615 2.7449E-16" rpy="0 0 0" />
            <mass value="0.060324" />
            <inertia ixx="0.051272" ixy="-7.472E-35" ixz="-2.4576E-34" iyy="0.094771" iyz="2.9633E-18" izz="0.051272" />
        </inertial>
        <visual>
            <origin xyz="0 0 0" rpy="0 0 0" />
            <geometry>
                <mesh filename="package://kuka_urdf/meshes/tableEeffortLink.STL" />
            </geometry>
            <material name="">
                <color rgba="1 1 1 1" />
            </material>
        </visual>
        <collision>
            <origin xyz="0 0 0" rpy="0 0 0" />
            <geometry>
                <mesh filename="package://kuka_urdf/meshes/tableEeffortLink.STL" />
            </geometry>
        </collision>
    </link>
    <joint name="tableEeffortJoint" type="fixed">
        <origin xyz="0 0 0" rpy="1.5708 0 0" />
        <parent link="tableLink2" />
        <child link="tableEeffortLink" />
        <axis xyz="0 0 0" />
    </joint>
    <transmission name="trans_joint1">
        <type>transmission_interface/SimpleTransmission</type>
        <joint name="joint1">
            <hardwareInterface>hardware_interface/EffortJointInterface</hardwareInterface>
        </joint>
        <actuator name="joint1_motor">
            <hardwareInterface>hardware_interface/EffortJointInterface</hardwareInterface>
            <mechanicalReduction>1</mechanicalReduction>
        </actuator>
    </transmission>
    <transmission name="trans_joint2">
        <type>transmission_interface/SimpleTransmission</type>
        <joint name="joint2">
            <hardwareInterface>hardware_interface/EffortJointInterface</hardwareInterface>
        </joint>
        <actuator name="joint2_motor">
            <hardwareInterface>hardware_interface/EffortJointInterface</hardwareInterface>
            <mechanicalReduction>1</mechanicalReduction>
        </actuator>
    </transmission>
    <transmission name="trans_joint3">
        <type>transmission_interface/SimpleTransmission</type>
        <joint name="joint3">
            <hardwareInterface>hardware_interface/EffortJointInterface</hardwareInterface>
        </joint>
        <actuator name="joint3_motor">
            <hardwareInterface>hardware_interface/EffortJointInterface</hardwareInterface>
            <mechanicalReduction>1</mechanicalReduction>
        </actuator>
    </transmission>
    <transmission name="trans_joint4">
        <type>transmission_interface/SimpleTransmission</type>
        <joint name="joint4">
            <hardwareInterface>hardware_interface/EffortJointInterface</hardwareInterface>
        </joint>
        <actuator name="joint4_motor">
            <hardwareInterface>hardware_interface/EffortJointInterface</hardwareInterface>
            <mechanicalReduction>1</mechanicalReduction>
        </actuator>
    </transmission>
    <transmission name="trans_joint5">
        <type>transmission_interface/SimpleTransmission</type>
        <joint name="joint5">
            <hardwareInterface>hardware_interface/EffortJointInterface</hardwareInterface>
        </joint>
        <actuator name="joint5_motor">
            <hardwareInterface>hardware_interface/EffortJointInterface</hardwareInterface>
            <mechanicalReduction>1</mechanicalReduction>
        </actuator>
    </transmission>
    <transmission name="trans_joint6">
        <type>transmission_interface/SimpleTransmission</type>
        <joint name="joint6">
            <hardwareInterface>hardware_interface/EffortJointInterface</hardwareInterface>
        </joint>
        <actuator name="joint6_motor">
            <hardwareInterface>hardware_interface/EffortJointInterface</hardwareInterface>
            <mechanicalReduction>1</mechanicalReduction>
        </actuator>
    </transmission>
    <transmission name="trans_tableJoint1">
        <type>transmission_interface/SimpleTransmission</type>
        <joint name="tableJoint1">
            <hardwareInterface>hardware_interface/EffortJointInterface</hardwareInterface>
        </joint>
        <actuator name="tableJoint1_motor">
            <hardwareInterface>hardware_interface/EffortJointInterface</hardwareInterface>
            <mechanicalReduction>1</mechanicalReduction>
        </actuator>
    </transmission>
    <transmission name="trans_tableJoint2">
        <type>transmission_interface/SimpleTransmission</type>
        <joint name="tableJoint2">
            <hardwareInterface>hardware_interface/EffortJointInterface</hardwareInterface>
        </joint>
        <actuator name="tableJoint2_motor">
            <hardwareInterface>hardware_interface/EffortJointInterface</hardwareInterface>
            <mechanicalReduction>1</mechanicalReduction>
        </actuator>
    </transmission>
    <gazebo>
        <plugin name="gazebo_ros_control" filename="libgazebo_ros_control.so">
            <robotNamespace>/</robotNamespace>
        </plugin>
    </gazebo>
</robot>

